[2022-02-19 10:12:36,650] {taskinstance.py:826} INFO - Dependencies all met for <TaskInstance: example_dag_decorator.get_ip 2022-02-19T10:12:34.769147+00:00 [queued]>
[2022-02-19 10:12:36,669] {taskinstance.py:826} INFO - Dependencies all met for <TaskInstance: example_dag_decorator.get_ip 2022-02-19T10:12:34.769147+00:00 [queued]>
[2022-02-19 10:12:36,670] {taskinstance.py:1017} INFO - 
--------------------------------------------------------------------------------
[2022-02-19 10:12:36,671] {taskinstance.py:1018} INFO - Starting attempt 1 of 1
[2022-02-19 10:12:36,671] {taskinstance.py:1019} INFO - 
--------------------------------------------------------------------------------
[2022-02-19 10:12:36,683] {taskinstance.py:1038} INFO - Executing <Task(GetRequestOperator): get_ip> on 2022-02-19T10:12:34.769147+00:00
[2022-02-19 10:12:36,687] {standard_task_runner.py:51} INFO - Started process 31 to run task
[2022-02-19 10:12:36,693] {standard_task_runner.py:75} INFO - Running: ['airflow', 'tasks', 'run', 'example_dag_decorator', 'get_ip', '2022-02-19T10:12:34.769147+00:00', '--job-id', '16', '--pool', 'default_pool', '--raw', '--subdir', '/home/airflow/.local/lib/python3.8/site-packages/airflow/example_dags/example_dag_decorator.py', '--cfg-path', '/tmp/tmpc8gw4ui4']
[2022-02-19 10:12:36,693] {standard_task_runner.py:76} INFO - Job 16: Subtask get_ip
[2022-02-19 10:12:36,746] {logging_mixin.py:103} INFO - Running <TaskInstance: example_dag_decorator.get_ip 2022-02-19T10:12:34.769147+00:00 [running]> on host c2bc2cd2c232
[2022-02-19 10:12:36,799] {taskinstance.py:1230} INFO - Exporting the following env vars:
AIRFLOW_CTX_DAG_OWNER=airflow
AIRFLOW_CTX_DAG_ID=example_dag_decorator
AIRFLOW_CTX_TASK_ID=get_ip
AIRFLOW_CTX_EXECUTION_DATE=2022-02-19T10:12:34.769147+00:00
AIRFLOW_CTX_DAG_RUN_ID=manual__2022-02-19T10:12:34.769147+00:00
[2022-02-19 10:12:46,818] {taskinstance.py:1396} ERROR - HTTPConnectionPool(host='httpbin.org', port=80): Max retries exceeded with url: /get (Caused by NewConnectionError('<urllib3.connection.HTTPConnection object at 0x7f2fe095a1f0>: Failed to establish a new connection: [Errno -3] Temporary failure in name resolution'))
Traceback (most recent call last):
  File "/home/airflow/.local/lib/python3.8/site-packages/urllib3/connection.py", line 159, in _new_conn
    conn = connection.create_connection(
  File "/home/airflow/.local/lib/python3.8/site-packages/urllib3/util/connection.py", line 61, in create_connection
    for res in socket.getaddrinfo(host, port, family, socket.SOCK_STREAM):
  File "/usr/local/lib/python3.8/socket.py", line 918, in getaddrinfo
    for res in _socket.getaddrinfo(host, port, family, type, proto, flags):
socket.gaierror: [Errno -3] Temporary failure in name resolution

During handling of the above exception, another exception occurred:

Traceback (most recent call last):
  File "/home/airflow/.local/lib/python3.8/site-packages/urllib3/connectionpool.py", line 670, in urlopen
    httplib_response = self._make_request(
  File "/home/airflow/.local/lib/python3.8/site-packages/urllib3/connectionpool.py", line 392, in _make_request
    conn.request(method, url, **httplib_request_kw)
  File "/usr/local/lib/python3.8/http/client.py", line 1255, in request
    self._send_request(method, url, body, headers, encode_chunked)
  File "/usr/local/lib/python3.8/http/client.py", line 1301, in _send_request
    self.endheaders(body, encode_chunked=encode_chunked)
  File "/usr/local/lib/python3.8/http/client.py", line 1250, in endheaders
    self._send_output(message_body, encode_chunked=encode_chunked)
  File "/usr/local/lib/python3.8/http/client.py", line 1010, in _send_output
    self.send(msg)
  File "/usr/local/lib/python3.8/http/client.py", line 950, in send
    self.connect()
  File "/home/airflow/.local/lib/python3.8/site-packages/urllib3/connection.py", line 187, in connect
    conn = self._new_conn()
  File "/home/airflow/.local/lib/python3.8/site-packages/urllib3/connection.py", line 171, in _new_conn
    raise NewConnectionError(
urllib3.exceptions.NewConnectionError: <urllib3.connection.HTTPConnection object at 0x7f2fe095a1f0>: Failed to establish a new connection: [Errno -3] Temporary failure in name resolution

During handling of the above exception, another exception occurred:

Traceback (most recent call last):
  File "/home/airflow/.local/lib/python3.8/site-packages/requests/adapters.py", line 439, in send
    resp = conn.urlopen(
  File "/home/airflow/.local/lib/python3.8/site-packages/urllib3/connectionpool.py", line 726, in urlopen
    retries = retries.increment(
  File "/home/airflow/.local/lib/python3.8/site-packages/urllib3/util/retry.py", line 446, in increment
    raise MaxRetryError(_pool, url, error or ResponseError(cause))
urllib3.exceptions.MaxRetryError: HTTPConnectionPool(host='httpbin.org', port=80): Max retries exceeded with url: /get (Caused by NewConnectionError('<urllib3.connection.HTTPConnection object at 0x7f2fe095a1f0>: Failed to establish a new connection: [Errno -3] Temporary failure in name resolution'))

During handling of the above exception, another exception occurred:

Traceback (most recent call last):
  File "/home/airflow/.local/lib/python3.8/site-packages/airflow/models/taskinstance.py", line 1086, in _run_raw_task
    self._prepare_and_execute_task_with_callbacks(context, task)
  File "/home/airflow/.local/lib/python3.8/site-packages/airflow/models/taskinstance.py", line 1260, in _prepare_and_execute_task_with_callbacks
    result = self._execute_task(context, task_copy)
  File "/home/airflow/.local/lib/python3.8/site-packages/airflow/models/taskinstance.py", line 1300, in _execute_task
    result = task_copy.execute(context=context)
  File "/home/airflow/.local/lib/python3.8/site-packages/airflow/example_dags/example_dag_decorator.py", line 40, in execute
    return requests.get(self.url).json()
  File "/home/airflow/.local/lib/python3.8/site-packages/requests/api.py", line 76, in get
    return request('get', url, params=params, **kwargs)
  File "/home/airflow/.local/lib/python3.8/site-packages/requests/api.py", line 61, in request
    return session.request(method=method, url=url, **kwargs)
  File "/home/airflow/.local/lib/python3.8/site-packages/requests/sessions.py", line 530, in request
    resp = self.send(prep, **send_kwargs)
  File "/home/airflow/.local/lib/python3.8/site-packages/requests/sessions.py", line 643, in send
    r = adapter.send(request, **kwargs)
  File "/home/airflow/.local/lib/python3.8/site-packages/requests/adapters.py", line 516, in send
    raise ConnectionError(e, request=request)
requests.exceptions.ConnectionError: HTTPConnectionPool(host='httpbin.org', port=80): Max retries exceeded with url: /get (Caused by NewConnectionError('<urllib3.connection.HTTPConnection object at 0x7f2fe095a1f0>: Failed to establish a new connection: [Errno -3] Temporary failure in name resolution'))
[2022-02-19 10:12:46,832] {taskinstance.py:1433} INFO - Marking task as FAILED. dag_id=example_dag_decorator, task_id=get_ip, execution_date=20220219T101234, start_date=20220219T101236, end_date=20220219T101246
[2022-02-19 10:12:46,876] {local_task_job.py:118} INFO - Task exited with return code 1
