[2022-04-28 13:11:39,276] {taskinstance.py:1032} INFO - Dependencies all met for <TaskInstance: cdn_daily.import_pre.run_pre.alm manual__2022-04-28T12:55:13.656507+00:00 [queued]>
[2022-04-28 13:11:39,313] {taskinstance.py:1032} INFO - Dependencies all met for <TaskInstance: cdn_daily.import_pre.run_pre.alm manual__2022-04-28T12:55:13.656507+00:00 [queued]>
[2022-04-28 13:11:39,321] {taskinstance.py:1238} INFO - 
--------------------------------------------------------------------------------
[2022-04-28 13:11:39,325] {taskinstance.py:1239} INFO - Starting attempt 2 of 2
[2022-04-28 13:11:39,328] {taskinstance.py:1240} INFO - 
--------------------------------------------------------------------------------
[2022-04-28 13:11:39,393] {taskinstance.py:1259} INFO - Executing <Task(PythonOperator): import_pre.run_pre.alm> on 2022-04-28 12:55:13.656507+00:00
[2022-04-28 13:11:39,405] {standard_task_runner.py:52} INFO - Started process 1237 to run task
[2022-04-28 13:11:39,418] {standard_task_runner.py:76} INFO - Running: ['***', 'tasks', 'run', 'cdn_daily', 'import_pre.run_pre.alm', 'manual__2022-04-28T12:55:13.656507+00:00', '--job-id', '1413', '--raw', '--subdir', 'DAGS_FOLDER/cdn_daily.py', '--cfg-path', '/tmp/tmp3r97y1b9', '--error-file', '/tmp/tmpt9z6vk2h']
[2022-04-28 13:11:39,420] {standard_task_runner.py:77} INFO - Job 1413: Subtask import_pre.run_pre.alm
[2022-04-28 13:11:39,644] {logging_mixin.py:109} INFO - Running <TaskInstance: cdn_daily.import_pre.run_pre.alm manual__2022-04-28T12:55:13.656507+00:00 [running]> on host d5ad096ffea5
[2022-04-28 13:11:39,793] {taskinstance.py:1426} INFO - Exporting the following env vars:
AIRFLOW_CTX_DAG_EMAIL=***@example.com
AIRFLOW_CTX_DAG_OWNER=***
AIRFLOW_CTX_DAG_ID=cdn_daily
AIRFLOW_CTX_TASK_ID=import_pre.run_pre.alm
AIRFLOW_CTX_EXECUTION_DATE=2022-04-28T12:55:13.656507+00:00
AIRFLOW_CTX_DAG_RUN_ID=manual__2022-04-28T12:55:13.656507+00:00
[2022-04-28 13:11:39,797] {taskinstance.py:1700} ERROR - Task failed with exception
Traceback (most recent call last):
  File "/home/airflow/.local/lib/python3.7/site-packages/airflow/models/taskinstance.py", line 1329, in _run_raw_task
    self._execute_task_with_callbacks(context)
  File "/home/airflow/.local/lib/python3.7/site-packages/airflow/models/taskinstance.py", line 1455, in _execute_task_with_callbacks
    result = self._execute_task(context, self.task)
  File "/home/airflow/.local/lib/python3.7/site-packages/airflow/models/taskinstance.py", line 1511, in _execute_task
    result = execute_callable(context=context)
  File "/home/airflow/.local/lib/python3.7/site-packages/airflow/operators/python.py", line 174, in execute
    return_value = self.execute_callable()
  File "/home/airflow/.local/lib/python3.7/site-packages/airflow/operators/python.py", line 185, in execute_callable
    return self.python_callable(*self.op_args, **self.op_kwargs)
  File "/opt/airflow/dags/commons/cdn_daily_functions.py", line 6, in run
    task_instance.xcom_push(key='process_name',value=process_name),
NameError: name 'task_instance' is not defined
[2022-04-28 13:11:39,857] {taskinstance.py:1277} INFO - Marking task as FAILED. dag_id=cdn_daily, task_id=import_pre.run_pre.alm, execution_date=20220428T125513, start_date=20220428T131139, end_date=20220428T131139
[2022-04-28 13:11:39,910] {standard_task_runner.py:92} ERROR - Failed to execute job 1413 for task import_pre.run_pre.alm
Traceback (most recent call last):
  File "/home/airflow/.local/lib/python3.7/site-packages/airflow/task/task_runner/standard_task_runner.py", line 85, in _start_by_fork
    args.func(args, dag=self.dag)
  File "/home/airflow/.local/lib/python3.7/site-packages/airflow/cli/cli_parser.py", line 48, in command
    return func(*args, **kwargs)
  File "/home/airflow/.local/lib/python3.7/site-packages/airflow/utils/cli.py", line 92, in wrapper
    return f(*args, **kwargs)
  File "/home/airflow/.local/lib/python3.7/site-packages/airflow/cli/commands/task_command.py", line 298, in task_run
    _run_task_by_selected_method(args, dag, ti)
  File "/home/airflow/.local/lib/python3.7/site-packages/airflow/cli/commands/task_command.py", line 107, in _run_task_by_selected_method
    _run_raw_task(args, ti)
  File "/home/airflow/.local/lib/python3.7/site-packages/airflow/cli/commands/task_command.py", line 184, in _run_raw_task
    error_file=args.error_file,
  File "/home/airflow/.local/lib/python3.7/site-packages/airflow/utils/session.py", line 70, in wrapper
    return func(*args, session=session, **kwargs)
  File "/home/airflow/.local/lib/python3.7/site-packages/airflow/models/taskinstance.py", line 1329, in _run_raw_task
    self._execute_task_with_callbacks(context)
  File "/home/airflow/.local/lib/python3.7/site-packages/airflow/models/taskinstance.py", line 1455, in _execute_task_with_callbacks
    result = self._execute_task(context, self.task)
  File "/home/airflow/.local/lib/python3.7/site-packages/airflow/models/taskinstance.py", line 1511, in _execute_task
    result = execute_callable(context=context)
  File "/home/airflow/.local/lib/python3.7/site-packages/airflow/operators/python.py", line 174, in execute
    return_value = self.execute_callable()
  File "/home/airflow/.local/lib/python3.7/site-packages/airflow/operators/python.py", line 185, in execute_callable
    return self.python_callable(*self.op_args, **self.op_kwargs)
  File "/opt/airflow/dags/commons/cdn_daily_functions.py", line 6, in run
    task_instance.xcom_push(key='process_name',value=process_name),
NameError: name 'task_instance' is not defined
[2022-04-28 13:11:39,939] {local_task_job.py:154} INFO - Task exited with return code 1
[2022-04-28 13:11:40,081] {local_task_job.py:264} INFO - 0 downstream tasks scheduled from follow-on schedule check
