[2022-04-28 13:11:38,578] {taskinstance.py:1032} INFO - Dependencies all met for <TaskInstance: cdn_daily.import_cat.check_presence_of_cat1 scheduled__2022-04-27T12:55:05.495602+00:00 [queued]>
[2022-04-28 13:11:38,607] {taskinstance.py:1032} INFO - Dependencies all met for <TaskInstance: cdn_daily.import_cat.check_presence_of_cat1 scheduled__2022-04-27T12:55:05.495602+00:00 [queued]>
[2022-04-28 13:11:38,609] {taskinstance.py:1238} INFO - 
--------------------------------------------------------------------------------
[2022-04-28 13:11:38,611] {taskinstance.py:1239} INFO - Starting attempt 2 of 2
[2022-04-28 13:11:38,612] {taskinstance.py:1240} INFO - 
--------------------------------------------------------------------------------
[2022-04-28 13:11:38,643] {taskinstance.py:1259} INFO - Executing <Task(PythonOperator): import_cat.check_presence_of_cat1> on 2022-04-27 12:55:05.495602+00:00
[2022-04-28 13:11:38,658] {standard_task_runner.py:52} INFO - Started process 1228 to run task
[2022-04-28 13:11:38,668] {standard_task_runner.py:76} INFO - Running: ['***', 'tasks', 'run', 'cdn_daily', 'import_cat.check_presence_of_cat1', 'scheduled__2022-04-27T12:55:05.495602+00:00', '--job-id', '1405', '--raw', '--subdir', 'DAGS_FOLDER/cdn_daily.py', '--cfg-path', '/tmp/tmp6srdohvp', '--error-file', '/tmp/tmpefq74azj']
[2022-04-28 13:11:38,674] {standard_task_runner.py:77} INFO - Job 1405: Subtask import_cat.check_presence_of_cat1
[2022-04-28 13:11:38,856] {logging_mixin.py:109} INFO - Running <TaskInstance: cdn_daily.import_cat.check_presence_of_cat1 scheduled__2022-04-27T12:55:05.495602+00:00 [running]> on host d5ad096ffea5
[2022-04-28 13:11:39,055] {taskinstance.py:1426} INFO - Exporting the following env vars:
AIRFLOW_CTX_DAG_EMAIL=***@example.com
AIRFLOW_CTX_DAG_OWNER=***
AIRFLOW_CTX_DAG_ID=cdn_daily
AIRFLOW_CTX_TASK_ID=import_cat.check_presence_of_cat1
AIRFLOW_CTX_EXECUTION_DATE=2022-04-27T12:55:05.495602+00:00
AIRFLOW_CTX_DAG_RUN_ID=scheduled__2022-04-27T12:55:05.495602+00:00
[2022-04-28 13:11:39,062] {taskinstance.py:1700} ERROR - Task failed with exception
Traceback (most recent call last):
  File "/home/airflow/.local/lib/python3.7/site-packages/airflow/models/taskinstance.py", line 1329, in _run_raw_task
    self._execute_task_with_callbacks(context)
  File "/home/airflow/.local/lib/python3.7/site-packages/airflow/models/taskinstance.py", line 1455, in _execute_task_with_callbacks
    result = self._execute_task(context, self.task)
  File "/home/airflow/.local/lib/python3.7/site-packages/airflow/models/taskinstance.py", line 1511, in _execute_task
    result = execute_callable(context=context)
  File "/home/airflow/.local/lib/python3.7/site-packages/airflow/operators/python.py", line 174, in execute
    return_value = self.execute_callable()
  File "/home/airflow/.local/lib/python3.7/site-packages/airflow/operators/python.py", line 185, in execute_callable
    return self.python_callable(*self.op_args, **self.op_kwargs)
  File "/opt/airflow/dags/commons/cdn_daily_functions.py", line 41, in files_check
    task_instance.xcom_push(key='filename',value=filename),
NameError: name 'task_instance' is not defined
[2022-04-28 13:11:39,130] {taskinstance.py:1277} INFO - Marking task as FAILED. dag_id=cdn_daily, task_id=import_cat.check_presence_of_cat1, execution_date=20220427T125505, start_date=20220428T131138, end_date=20220428T131139
[2022-04-28 13:11:39,320] {standard_task_runner.py:92} ERROR - Failed to execute job 1405 for task import_cat.check_presence_of_cat1
Traceback (most recent call last):
  File "/home/airflow/.local/lib/python3.7/site-packages/airflow/task/task_runner/standard_task_runner.py", line 85, in _start_by_fork
    args.func(args, dag=self.dag)
  File "/home/airflow/.local/lib/python3.7/site-packages/airflow/cli/cli_parser.py", line 48, in command
    return func(*args, **kwargs)
  File "/home/airflow/.local/lib/python3.7/site-packages/airflow/utils/cli.py", line 92, in wrapper
    return f(*args, **kwargs)
  File "/home/airflow/.local/lib/python3.7/site-packages/airflow/cli/commands/task_command.py", line 298, in task_run
    _run_task_by_selected_method(args, dag, ti)
  File "/home/airflow/.local/lib/python3.7/site-packages/airflow/cli/commands/task_command.py", line 107, in _run_task_by_selected_method
    _run_raw_task(args, ti)
  File "/home/airflow/.local/lib/python3.7/site-packages/airflow/cli/commands/task_command.py", line 184, in _run_raw_task
    error_file=args.error_file,
  File "/home/airflow/.local/lib/python3.7/site-packages/airflow/utils/session.py", line 70, in wrapper
    return func(*args, session=session, **kwargs)
  File "/home/airflow/.local/lib/python3.7/site-packages/airflow/models/taskinstance.py", line 1329, in _run_raw_task
    self._execute_task_with_callbacks(context)
  File "/home/airflow/.local/lib/python3.7/site-packages/airflow/models/taskinstance.py", line 1455, in _execute_task_with_callbacks
    result = self._execute_task(context, self.task)
  File "/home/airflow/.local/lib/python3.7/site-packages/airflow/models/taskinstance.py", line 1511, in _execute_task
    result = execute_callable(context=context)
  File "/home/airflow/.local/lib/python3.7/site-packages/airflow/operators/python.py", line 174, in execute
    return_value = self.execute_callable()
  File "/home/airflow/.local/lib/python3.7/site-packages/airflow/operators/python.py", line 185, in execute_callable
    return self.python_callable(*self.op_args, **self.op_kwargs)
  File "/opt/airflow/dags/commons/cdn_daily_functions.py", line 41, in files_check
    task_instance.xcom_push(key='filename',value=filename),
NameError: name 'task_instance' is not defined
[2022-04-28 13:11:39,383] {local_task_job.py:154} INFO - Task exited with return code 1
[2022-04-28 13:11:39,668] {local_task_job.py:264} INFO - 0 downstream tasks scheduled from follow-on schedule check
