[2022-03-29 14:17:12,708] {taskinstance.py:1032} INFO - Dependencies all met for <TaskInstance: tutorial.hfghfg.hfghfg_get_data scheduled__2022-03-28T12:54:27.698780+00:00 [queued]>
[2022-03-29 14:17:12,780] {taskinstance.py:1032} INFO - Dependencies all met for <TaskInstance: tutorial.hfghfg.hfghfg_get_data scheduled__2022-03-28T12:54:27.698780+00:00 [queued]>
[2022-03-29 14:17:12,782] {taskinstance.py:1238} INFO - 
--------------------------------------------------------------------------------
[2022-03-29 14:17:12,783] {taskinstance.py:1239} INFO - Starting attempt 1 of 2
[2022-03-29 14:17:12,785] {taskinstance.py:1240} INFO - 
--------------------------------------------------------------------------------
[2022-03-29 14:17:12,834] {taskinstance.py:1259} INFO - Executing <Task(PythonOperator): hfghfg.hfghfg_get_data> on 2022-03-28 12:54:27.698780+00:00
[2022-03-29 14:17:12,841] {standard_task_runner.py:52} INFO - Started process 889 to run task
[2022-03-29 14:17:12,849] {standard_task_runner.py:76} INFO - Running: ['***', 'tasks', 'run', 'tutorial', 'hfghfg.hfghfg_get_data', 'scheduled__2022-03-28T12:54:27.698780+00:00', '--job-id', '1043', '--raw', '--subdir', 'DAGS_FOLDER/test_dag.py', '--cfg-path', '/tmp/tmppd7aoxug', '--error-file', '/tmp/tmpp44_xa6b']
[2022-03-29 14:17:12,852] {standard_task_runner.py:77} INFO - Job 1043: Subtask hfghfg.hfghfg_get_data
[2022-03-29 14:17:13,154] {logging_mixin.py:109} INFO - Running <TaskInstance: tutorial.hfghfg.hfghfg_get_data scheduled__2022-03-28T12:54:27.698780+00:00 [running]> on host ff48034dfdbf
[2022-03-29 14:17:13,369] {taskinstance.py:1426} INFO - Exporting the following env vars:
AIRFLOW_CTX_DAG_EMAIL=***@example.com
AIRFLOW_CTX_DAG_OWNER=***
AIRFLOW_CTX_DAG_ID=tutorial
AIRFLOW_CTX_TASK_ID=hfghfg.hfghfg_get_data
AIRFLOW_CTX_EXECUTION_DATE=2022-03-28T12:54:27.698780+00:00
AIRFLOW_CTX_DAG_RUN_ID=scheduled__2022-03-28T12:54:27.698780+00:00
[2022-03-29 16:17:46,698] {local_task_job.py:212} WARNING - State of this instance has been externally set to up_for_retry. Terminating instance.
[2022-03-29 16:17:46,705] {process_utils.py:124} INFO - Sending Signals.SIGTERM to group 889. PIDs of all processes in the group: [889]
[2022-03-29 16:17:46,711] {process_utils.py:75} INFO - Sending the signal Signals.SIGTERM to group 889
[2022-03-29 16:17:46,716] {taskinstance.py:1408} ERROR - Received SIGTERM. Terminating subprocesses.
[2022-03-29 16:17:46,850] {taskinstance.py:1700} ERROR - Task failed with exception
Traceback (most recent call last):
  File "/home/airflow/.local/lib/python3.7/site-packages/airflow/models/taskinstance.py", line 1329, in _run_raw_task
    self._execute_task_with_callbacks(context)
  File "/home/airflow/.local/lib/python3.7/site-packages/airflow/models/taskinstance.py", line 1455, in _execute_task_with_callbacks
    result = self._execute_task(context, self.task)
  File "/home/airflow/.local/lib/python3.7/site-packages/airflow/models/taskinstance.py", line 1511, in _execute_task
    result = execute_callable(context=context)
  File "/home/airflow/.local/lib/python3.7/site-packages/airflow/operators/python.py", line 174, in execute
    return_value = self.execute_callable()
  File "/home/airflow/.local/lib/python3.7/site-packages/airflow/operators/python.py", line 185, in execute_callable
    return self.python_callable(*self.op_args, **self.op_kwargs)
  File "/opt/airflow/dags/test_dag.py", line 35, in task_pause
    time.sleep(60)
  File "/home/airflow/.local/lib/python3.7/site-packages/airflow/models/taskinstance.py", line 1410, in signal_handler
    raise AirflowException("Task received SIGTERM signal")
airflow.exceptions.AirflowException: Task received SIGTERM signal
[2022-03-29 16:17:46,881] {taskinstance.py:1277} INFO - Marking task as FAILED. dag_id=tutorial, task_id=hfghfg.hfghfg_get_data, execution_date=20220328T125427, start_date=20220329T141712, end_date=20220329T161746
[2022-03-29 16:17:46,909] {standard_task_runner.py:92} ERROR - Failed to execute job 1043 for task hfghfg.hfghfg_get_data
Traceback (most recent call last):
  File "/home/airflow/.local/lib/python3.7/site-packages/airflow/task/task_runner/standard_task_runner.py", line 85, in _start_by_fork
    args.func(args, dag=self.dag)
  File "/home/airflow/.local/lib/python3.7/site-packages/airflow/cli/cli_parser.py", line 48, in command
    return func(*args, **kwargs)
  File "/home/airflow/.local/lib/python3.7/site-packages/airflow/utils/cli.py", line 92, in wrapper
    return f(*args, **kwargs)
  File "/home/airflow/.local/lib/python3.7/site-packages/airflow/cli/commands/task_command.py", line 298, in task_run
    _run_task_by_selected_method(args, dag, ti)
  File "/home/airflow/.local/lib/python3.7/site-packages/airflow/cli/commands/task_command.py", line 107, in _run_task_by_selected_method
    _run_raw_task(args, ti)
  File "/home/airflow/.local/lib/python3.7/site-packages/airflow/cli/commands/task_command.py", line 184, in _run_raw_task
    error_file=args.error_file,
  File "/home/airflow/.local/lib/python3.7/site-packages/airflow/utils/session.py", line 70, in wrapper
    return func(*args, session=session, **kwargs)
  File "/home/airflow/.local/lib/python3.7/site-packages/airflow/models/taskinstance.py", line 1329, in _run_raw_task
    self._execute_task_with_callbacks(context)
  File "/home/airflow/.local/lib/python3.7/site-packages/airflow/models/taskinstance.py", line 1455, in _execute_task_with_callbacks
    result = self._execute_task(context, self.task)
  File "/home/airflow/.local/lib/python3.7/site-packages/airflow/models/taskinstance.py", line 1511, in _execute_task
    result = execute_callable(context=context)
  File "/home/airflow/.local/lib/python3.7/site-packages/airflow/operators/python.py", line 174, in execute
    return_value = self.execute_callable()
  File "/home/airflow/.local/lib/python3.7/site-packages/airflow/operators/python.py", line 185, in execute_callable
    return self.python_callable(*self.op_args, **self.op_kwargs)
  File "/opt/airflow/dags/test_dag.py", line 35, in task_pause
    time.sleep(60)
  File "/home/airflow/.local/lib/python3.7/site-packages/airflow/models/taskinstance.py", line 1410, in signal_handler
    raise AirflowException("Task received SIGTERM signal")
airflow.exceptions.AirflowException: Task received SIGTERM signal
[2022-03-29 16:17:46,943] {process_utils.py:70} INFO - Process psutil.Process(pid=889, status='terminated', exitcode=1, started='14:17:12') (889) terminated with exit code 1
