[2022-03-30 16:04:56,386] {taskinstance.py:1032} INFO - Dependencies all met for <TaskInstance: tutorial.jghjg.jghjg_get_data scheduled__2022-03-29T16:04:54.591828+00:00 [queued]>
[2022-03-30 16:04:56,421] {taskinstance.py:1032} INFO - Dependencies all met for <TaskInstance: tutorial.jghjg.jghjg_get_data scheduled__2022-03-29T16:04:54.591828+00:00 [queued]>
[2022-03-30 16:04:56,423] {taskinstance.py:1238} INFO - 
--------------------------------------------------------------------------------
[2022-03-30 16:04:56,425] {taskinstance.py:1239} INFO - Starting attempt 1 of 2
[2022-03-30 16:04:56,427] {taskinstance.py:1240} INFO - 
--------------------------------------------------------------------------------
[2022-03-30 16:04:56,450] {taskinstance.py:1259} INFO - Executing <Task(PythonOperator): jghjg.jghjg_get_data> on 2022-03-29 16:04:54.591828+00:00
[2022-03-30 16:04:56,462] {standard_task_runner.py:52} INFO - Started process 360 to run task
[2022-03-30 16:04:56,470] {standard_task_runner.py:76} INFO - Running: ['***', 'tasks', 'run', 'tutorial', 'jghjg.jghjg_get_data', 'scheduled__2022-03-29T16:04:54.591828+00:00', '--job-id', '1079', '--raw', '--subdir', 'DAGS_FOLDER/test_dag.py', '--cfg-path', '/tmp/tmpjvj7k7wb', '--error-file', '/tmp/tmphfcuwsj6']
[2022-03-30 16:04:56,474] {standard_task_runner.py:77} INFO - Job 1079: Subtask jghjg.jghjg_get_data
[2022-03-30 16:04:56,626] {logging_mixin.py:109} INFO - Running <TaskInstance: tutorial.jghjg.jghjg_get_data scheduled__2022-03-29T16:04:54.591828+00:00 [running]> on host ff48034dfdbf
[2022-03-30 16:04:56,801] {taskinstance.py:1426} INFO - Exporting the following env vars:
AIRFLOW_CTX_DAG_EMAIL=***@example.com
AIRFLOW_CTX_DAG_OWNER=***
AIRFLOW_CTX_DAG_ID=tutorial
AIRFLOW_CTX_TASK_ID=jghjg.jghjg_get_data
AIRFLOW_CTX_EXECUTION_DATE=2022-03-29T16:04:54.591828+00:00
AIRFLOW_CTX_DAG_RUN_ID=scheduled__2022-03-29T16:04:54.591828+00:00
[2022-03-30 16:48:00,862] {local_task_job.py:212} WARNING - State of this instance has been externally set to up_for_retry. Terminating instance.
[2022-03-30 16:48:00,871] {process_utils.py:124} INFO - Sending Signals.SIGTERM to group 360. PIDs of all processes in the group: [360]
[2022-03-30 16:48:00,877] {process_utils.py:75} INFO - Sending the signal Signals.SIGTERM to group 360
[2022-03-30 16:48:00,889] {taskinstance.py:1408} ERROR - Received SIGTERM. Terminating subprocesses.
[2022-03-30 16:48:01,420] {taskinstance.py:1700} ERROR - Task failed with exception
Traceback (most recent call last):
  File "/home/airflow/.local/lib/python3.7/site-packages/airflow/models/taskinstance.py", line 1329, in _run_raw_task
    self._execute_task_with_callbacks(context)
  File "/home/airflow/.local/lib/python3.7/site-packages/airflow/models/taskinstance.py", line 1455, in _execute_task_with_callbacks
    result = self._execute_task(context, self.task)
  File "/home/airflow/.local/lib/python3.7/site-packages/airflow/models/taskinstance.py", line 1511, in _execute_task
    result = execute_callable(context=context)
  File "/home/airflow/.local/lib/python3.7/site-packages/airflow/operators/python.py", line 174, in execute
    return_value = self.execute_callable()
  File "/home/airflow/.local/lib/python3.7/site-packages/airflow/operators/python.py", line 185, in execute_callable
    return self.python_callable(*self.op_args, **self.op_kwargs)
  File "/opt/airflow/dags/test_dag.py", line 35, in task_pause
    time.sleep(60)
  File "/home/airflow/.local/lib/python3.7/site-packages/airflow/models/taskinstance.py", line 1410, in signal_handler
    raise AirflowException("Task received SIGTERM signal")
airflow.exceptions.AirflowException: Task received SIGTERM signal
[2022-03-30 16:48:01,439] {taskinstance.py:1277} INFO - Marking task as FAILED. dag_id=tutorial, task_id=jghjg.jghjg_get_data, execution_date=20220329T160454, start_date=20220330T160456, end_date=20220330T164801
[2022-03-30 16:48:01,460] {standard_task_runner.py:92} ERROR - Failed to execute job 1079 for task jghjg.jghjg_get_data
Traceback (most recent call last):
  File "/home/airflow/.local/lib/python3.7/site-packages/airflow/task/task_runner/standard_task_runner.py", line 85, in _start_by_fork
    args.func(args, dag=self.dag)
  File "/home/airflow/.local/lib/python3.7/site-packages/airflow/cli/cli_parser.py", line 48, in command
    return func(*args, **kwargs)
  File "/home/airflow/.local/lib/python3.7/site-packages/airflow/utils/cli.py", line 92, in wrapper
    return f(*args, **kwargs)
  File "/home/airflow/.local/lib/python3.7/site-packages/airflow/cli/commands/task_command.py", line 298, in task_run
    _run_task_by_selected_method(args, dag, ti)
  File "/home/airflow/.local/lib/python3.7/site-packages/airflow/cli/commands/task_command.py", line 107, in _run_task_by_selected_method
    _run_raw_task(args, ti)
  File "/home/airflow/.local/lib/python3.7/site-packages/airflow/cli/commands/task_command.py", line 184, in _run_raw_task
    error_file=args.error_file,
  File "/home/airflow/.local/lib/python3.7/site-packages/airflow/utils/session.py", line 70, in wrapper
    return func(*args, session=session, **kwargs)
  File "/home/airflow/.local/lib/python3.7/site-packages/airflow/models/taskinstance.py", line 1329, in _run_raw_task
    self._execute_task_with_callbacks(context)
  File "/home/airflow/.local/lib/python3.7/site-packages/airflow/models/taskinstance.py", line 1455, in _execute_task_with_callbacks
    result = self._execute_task(context, self.task)
  File "/home/airflow/.local/lib/python3.7/site-packages/airflow/models/taskinstance.py", line 1511, in _execute_task
    result = execute_callable(context=context)
  File "/home/airflow/.local/lib/python3.7/site-packages/airflow/operators/python.py", line 174, in execute
    return_value = self.execute_callable()
  File "/home/airflow/.local/lib/python3.7/site-packages/airflow/operators/python.py", line 185, in execute_callable
    return self.python_callable(*self.op_args, **self.op_kwargs)
  File "/opt/airflow/dags/test_dag.py", line 35, in task_pause
    time.sleep(60)
  File "/home/airflow/.local/lib/python3.7/site-packages/airflow/models/taskinstance.py", line 1410, in signal_handler
    raise AirflowException("Task received SIGTERM signal")
airflow.exceptions.AirflowException: Task received SIGTERM signal
[2022-03-30 16:48:01,494] {process_utils.py:70} INFO - Process psutil.Process(pid=360, status='terminated', exitcode=1, started='16:04:55') (360) terminated with exit code 1
